<?xml version="1.0" ?>
<robot name="climbingrobot" xmlns:xacro="http://ros.org/wiki/xacro">
    
    <!--- new_gazebo_version should be false by default because pinocchio needs it!-->
    <xacro:arg name="robot_name" default="climbingrobot"/> 
    <xacro:arg name="new_gazebo_version" default="false"/>	


    <xacro:include filename="$(find climbingrobot_description)/gazebo/gazebo.urdf.xacro">
        <xacro:arg name="task_period" value="$(arg task_period)"/>
	<xacro:arg name="robot_name" value="$(arg robot_name)"/>
    </xacro:include>


    <!-- BASE LINK -->
    <!-- floating type is supported in older versions of Gazebo. In new Gazebo if a link has no parent, it is supposed to be attached to a floating joint -->

    <xacro:unless value="$(arg new_gazebo_version)">  
        <!-- Floating-base Joint -->
        <link name="world"/>
        <joint name="floating_base_joint" type="floating" >
            <origin rpy="0 0 0" xyz="0 0 0"/>
            <parent link="world"/>
            <child link="base_link"/>
        </joint>
    </xacro:unless>

    <link name="base_link" />    
    <joint name="floating_base" type="fixed">
        <origin rpy="0 0 0" xyz="0 0 0"/>
        <parent link="base_link"/>
        <child link="trunk"/>
    </joint>








    
    <link name="trunk">
        <!-- TODO the trunk (it will be fixed to base link but it has inertia) -->


    </link>


    
</robot>
